[2021-10-02 19:28:15,849] {taskinstance.py:903} INFO - Dependencies all met for <TaskInstance: my_dag.Choose_Best_Model 2021-10-02T19:28:13.149551+00:00 [queued]>
[2021-10-02 19:28:15,868] {taskinstance.py:903} INFO - Dependencies all met for <TaskInstance: my_dag.Choose_Best_Model 2021-10-02T19:28:13.149551+00:00 [queued]>
[2021-10-02 19:28:15,869] {taskinstance.py:1095} INFO - 
--------------------------------------------------------------------------------
[2021-10-02 19:28:15,870] {taskinstance.py:1096} INFO - Starting attempt 1 of 1
[2021-10-02 19:28:15,871] {taskinstance.py:1097} INFO - 
--------------------------------------------------------------------------------
[2021-10-02 19:28:15,880] {taskinstance.py:1115} INFO - Executing <Task(BranchPythonOperator): Choose_Best_Model> on 2021-10-02T19:28:13.149551+00:00
[2021-10-02 19:28:15,884] {standard_task_runner.py:52} INFO - Started process 20805 to run task
[2021-10-02 19:28:15,888] {standard_task_runner.py:76} INFO - Running: ['***', 'tasks', 'run', 'my_dag', 'Choose_Best_Model', '2021-10-02T19:28:13.149551+00:00', '--job-id', '40', '--pool', 'default_pool', '--raw', '--subdir', 'DAGS_FOLDER/my_dag.py', '--cfg-path', '/tmp/tmp501e2g7p', '--error-file', '/tmp/tmp5ugqytcj']
[2021-10-02 19:28:15,890] {standard_task_runner.py:77} INFO - Job 40: Subtask Choose_Best_Model
[2021-10-02 19:28:15,943] {logging_mixin.py:109} INFO - Running <TaskInstance: my_dag.Choose_Best_Model 2021-10-02T19:28:13.149551+00:00 [running]> on host d6b4131456ad
[2021-10-02 19:28:16,001] {taskinstance.py:1254} INFO - Exporting the following env vars:
AIRFLOW_CTX_DAG_OWNER=***
AIRFLOW_CTX_DAG_ID=my_dag
AIRFLOW_CTX_TASK_ID=Choose_Best_Model
AIRFLOW_CTX_EXECUTION_DATE=2021-10-02T19:28:13.149551+00:00
AIRFLOW_CTX_DAG_RUN_ID=manual__2021-10-02T19:28:13.149551+00:00
[2021-10-02 19:28:16,011] {taskinstance.py:1463} ERROR - Task failed with exception
Traceback (most recent call last):
  File "/home/airflow/.local/lib/python3.6/site-packages/airflow/models/taskinstance.py", line 1165, in _run_raw_task
    self._prepare_and_execute_task_with_callbacks(context, task)
  File "/home/airflow/.local/lib/python3.6/site-packages/airflow/models/taskinstance.py", line 1283, in _prepare_and_execute_task_with_callbacks
    result = self._execute_task(context, task_copy)
  File "/home/airflow/.local/lib/python3.6/site-packages/airflow/models/taskinstance.py", line 1313, in _execute_task
    result = task_copy.execute(context=context)
  File "/home/airflow/.local/lib/python3.6/site-packages/airflow/operators/python.py", line 179, in execute
    branch = super().execute(context)
  File "/home/airflow/.local/lib/python3.6/site-packages/airflow/operators/python.py", line 150, in execute
    return_value = self.execute_callable()
  File "/home/airflow/.local/lib/python3.6/site-packages/airflow/operators/python.py", line 161, in execute_callable
    return self.python_callable(*self.op_args, **self.op_kwargs)
  File "/opt/airflow/dags/my_dag.py", line 20, in _choose_best_model
    best_accuracy = max(accuracies)
TypeError: '>' not supported between instances of 'NoneType' and 'NoneType'
[2021-10-02 19:28:16,015] {taskinstance.py:1513} INFO - Marking task as FAILED. dag_id=my_dag, task_id=Choose_Best_Model, execution_date=20211002T192813, start_date=20211002T192815, end_date=20211002T192816
[2021-10-02 19:28:16,067] {local_task_job.py:151} INFO - Task exited with return code 1
[2021-10-02 19:28:16,138] {local_task_job.py:261} INFO - 0 downstream tasks scheduled from follow-on schedule check
