[2021-10-03 00:33:48,845] {taskinstance.py:903} INFO - Dependencies all met for <TaskInstance: my_dag.Not_Accurate 2021-10-03T00:33:45.208996+00:00 [queued]>
[2021-10-03 00:33:48,868] {taskinstance.py:903} INFO - Dependencies all met for <TaskInstance: my_dag.Not_Accurate 2021-10-03T00:33:45.208996+00:00 [queued]>
[2021-10-03 00:33:48,870] {taskinstance.py:1095} INFO - 
--------------------------------------------------------------------------------
[2021-10-03 00:33:48,871] {taskinstance.py:1096} INFO - Starting attempt 1 of 1
[2021-10-03 00:33:48,871] {taskinstance.py:1097} INFO - 
--------------------------------------------------------------------------------
[2021-10-03 00:33:48,886] {taskinstance.py:1115} INFO - Executing <Task(BashOperator): Not_Accurate> on 2021-10-03T00:33:45.208996+00:00
[2021-10-03 00:33:48,891] {standard_task_runner.py:52} INFO - Started process 23984 to run task
[2021-10-03 00:33:48,898] {standard_task_runner.py:76} INFO - Running: ['***', 'tasks', 'run', 'my_dag', 'Not_Accurate', '2021-10-03T00:33:45.208996+00:00', '--job-id', '57', '--pool', 'default_pool', '--raw', '--subdir', 'DAGS_FOLDER/my_dag.py', '--cfg-path', '/tmp/tmpeanw4_z0', '--error-file', '/tmp/tmpagig2skc']
[2021-10-03 00:33:48,900] {standard_task_runner.py:77} INFO - Job 57: Subtask Not_Accurate
[2021-10-03 00:33:48,966] {logging_mixin.py:109} INFO - Running <TaskInstance: my_dag.Not_Accurate 2021-10-03T00:33:45.208996+00:00 [running]> on host d6b4131456ad
[2021-10-03 00:33:49,086] {taskinstance.py:1254} INFO - Exporting the following env vars:
AIRFLOW_CTX_DAG_OWNER=***
AIRFLOW_CTX_DAG_ID=my_dag
AIRFLOW_CTX_TASK_ID=Not_Accurate
AIRFLOW_CTX_EXECUTION_DATE=2021-10-03T00:33:45.208996+00:00
AIRFLOW_CTX_DAG_RUN_ID=manual__2021-10-03T00:33:45.208996+00:00
[2021-10-03 00:33:49,091] {subprocess.py:52} INFO - Tmp dir root location: 
 /tmp
[2021-10-03 00:33:49,097] {subprocess.py:63} INFO - Running command: ['bash', '-c', "echo 'Not Accurate"]
[2021-10-03 00:33:49,131] {subprocess.py:74} INFO - Output:
[2021-10-03 00:33:49,140] {subprocess.py:78} INFO - bash: -c: line 0: unexpected EOF while looking for matching `''
[2021-10-03 00:33:49,141] {subprocess.py:78} INFO - bash: -c: line 1: syntax error: unexpected end of file
[2021-10-03 00:33:49,143] {subprocess.py:82} INFO - Command exited with return code 1
[2021-10-03 00:33:49,163] {taskinstance.py:1463} ERROR - Task failed with exception
Traceback (most recent call last):
  File "/home/airflow/.local/lib/python3.6/site-packages/airflow/models/taskinstance.py", line 1165, in _run_raw_task
    self._prepare_and_execute_task_with_callbacks(context, task)
  File "/home/airflow/.local/lib/python3.6/site-packages/airflow/models/taskinstance.py", line 1283, in _prepare_and_execute_task_with_callbacks
    result = self._execute_task(context, task_copy)
  File "/home/airflow/.local/lib/python3.6/site-packages/airflow/models/taskinstance.py", line 1313, in _execute_task
    result = task_copy.execute(context=context)
  File "/home/airflow/.local/lib/python3.6/site-packages/airflow/operators/bash.py", line 176, in execute
    raise AirflowException('Bash command failed. The command returned a non-zero exit code.')
airflow.exceptions.AirflowException: Bash command failed. The command returned a non-zero exit code.
[2021-10-03 00:33:49,167] {taskinstance.py:1513} INFO - Marking task as FAILED. dag_id=my_dag, task_id=Not_Accurate, execution_date=20211003T003345, start_date=20211003T003348, end_date=20211003T003349
[2021-10-03 00:33:49,198] {local_task_job.py:151} INFO - Task exited with return code 1
[2021-10-03 00:33:49,227] {local_task_job.py:261} INFO - 0 downstream tasks scheduled from follow-on schedule check
